Workbook
Name Slicer_Trim: #N/A

Sheet 0 - Portada
A1: PROYECTO EVALUADOR 2 — FERRETERIA LOS ROBLES — VERSION 01
A2: Excel para Negocios BCC 1001 IIC-2026 LEAD University
A4: VERSION ASIGNADA: | B4: 01
A6: Entrega Excel grupal: | B6: Martes 18 de agosto, 2026 — 11:59 am
A7: Entrega analisis individual: | B7: Martes 18 de agosto, 2026 — 11:59 am (cada integrante sube su propio documento por separado)
A8: Defensa oral: | B8: Individual — 2 preguntas por estudiante — ver hoja Tips_Defensa
A10: Este archivo es UNICO para su trio. Usar datos de otra version constituye fraude academico (nota cero + reporte).
A12: INTEGRANTES DEL TRIO
A13: Nombre completo / Carne (Integrante 1): | B13: Santiago Lara
A14: Nombre completo / Carne (Integrante 2): | B14: Camila Marin
A15: Nombre completo / Carne (Integrante 3): | B15: Yeremy Marin
A17: CONTENIDO DEL ARCHIVO
A18: Hoja | B18: Que contiene
A19: Catalogo_Productos | B19: Referencia con 30 productos: codigo, nombre, categoria, precio y costo unitario
A20: Reto1_Datos | B20: ESPACIOS + BUSCARV: limpiar codigos y completar las 90 transacciones
A21: Reto2_Logica | B21: SI anidado + SUMAR.SI: clasificar ventas y tabla resumen por sucursal
A22: Reto3_Estadisticas | B22: Estadisticas descriptivas por sucursal + 4 preguntas de analisis
A23: Reto4_TablaDin | B23: Tabla dinamica + campo calculado Margen + segmentador + 4 preguntas
A24: Reto5_Financiero | B24: PAGO + VAN + TIR: credito y evaluacion de dos escenarios de inversion
A25: Reto6_Dashboard | B25: Graficos estrategicos + 4 preguntas de analisis grupal
A26: Analisis_Individual | B26: Instrucciones y preguntas del documento individual que entrega cada uno
A27: Tips_Defensa | B27: Guia con ejemplos para preparar la defensa oral

Sheet Catalogo_Productos
A1: CATALOGO DE PRODUCTOS — FERRETERIA LOS ROBLES
A2: Referencia para el BUSCARV del Reto 1. NO modificar esta hoja.
A3: Codigo | B3: Nombre del Producto | C3: Categoria | D3: Precio Unit. | E3: Costo Unit.
A4: CON-001 | B4: Bloque 15x20x40 | C4: Construccion | D4: 850 | E4: 510
A5: CON-002 | B5: Cemento 50kg | C5: Construccion | D5: 8500 | E5: 5100
A6: CON-003 | B6: Varilla #3 (6m) | C6: Construccion | D6: 3200 | E6: 1920
A7: CON-004 | B7: Arena (m3) | C7: Construccion | D7: 12000 | E7: 7200
A8: CON-005 | B8: Malla electrosoldada | C8: Construccion | D8: 15000 | E8: 9000
A9: CON-006 | B9: Regla aluminio 2m | C9: Construccion | D9: 4500 | E9: 2700
A10: PIN-001 | B10: Pintura blanca 4L | C10: Pintura | D10: 15500 | E10: 9300
A11: PIN-002 | B11: Sellador acrilico | C11: Pintura | D11: 12000 | E11: 7200
A12: PIN-003 | B12: Thinner industrial | C12: Pintura | D12: 9800 | E12: 5880
A13: PIN-004 | B13: Pintura epoxica 1L | C13: Pintura | D13: 28000 | E13: 16800
A14: PIN-005 | B14: Rodillo de esponja | C14: Pintura | D14: 4500 | E14: 2700
A15: PIN-006 | B15: Brocha 4 pulgadas | C15: Pintura | D15: 3200 | E15: 1920
... A33: PLO-006 | B33: Tee PVC 1/2 | C33: Plomeria | D33: 380 | E33: 228

Sheet Reto1_Datos
A1: RETO 1 — LIMPIEZA CON ESPACIOS() Y COMPLETAR CON BUSCARV
A2: ENUNCIADO: Las 90 transacciones contienen un problema oculto: algunos codigos de producto en la columna F tienen espacios en blanco al inicio o al final. Esto impide que BUSCARV encuentre el producto en el catalogo. Su tarea: (1) limpiar cada codigo con ESPACIOS(), (2) usar BUSCARV para completar nombre, categoria, precio unitario y costo unitario desde el catalogo, y (3) calcular los totales de venta y costo por fila.
A4: PREGUNTAS DEL RETO 1
A5: R1-P1: Una vez completada la tabla, cuantas transacciones corresponden a la sucursal Central? Use una funcion de conteo al pie de la tabla para respaldar su respuesta.
A6: =COUNTIF(D18:D107,"Central") -> 18
A8: R1-P2: Cual es el total general de ventas (suma de la columna Total Venta) de las 90 transacciones de su version?
A9: =SUM(L18:L107) -> 23139300
A11: R1-P3: Por que es imprescindible aplicar ESPACIOS() antes del BUSCARV? Que mensaje de error aparece en Excel si no se limpian los codigos y por que ocurre?
A12: La funcion ESPACIOS (TRIM) es imprescindible porque BUSCARV (VLOOKUP) con el cuarto argumento en 0 exige una coincidencia EXACTA entre el valor buscado y el valor del catalogo. Un codigo como " CON-001" (con un espacio en blanco al inicio) no es identico, caracter por caracter, al "CON-001" que existe en la columna A del catalogo, aunque visualmente parezcan iguales. Si no se limpia el codigo primero, BUSCARV no encuentra ninguna coincidencia y Excel devuelve el error #N/A ("valor no disponible"), lo que a su vez rompe las columnas de Nombre, Precio y Costo y los totales calculados a partir de ellas. Al envolver la referencia en ESPACIOS() antes de buscarla, se eliminan los espacios sobrantes al inicio y al final del texto y el codigo queda identico al del catalogo, por lo que BUSCARV encuentra la fila correcta.
A15: COMO USAR ESPACIOS(): Identifique la columna del codigo original. La funcion ESPACIOS(texto) elimina espacios en blanco al inicio y al final de una cadena. Sintaxis: =ESPACIOS(referencia_de_celda). Apliquela en cada fila de la columna "Cod. Limpio" apuntando al codigo original correspondiente. COMO USAR BUSCARV(): Una vez que tiene el codigo limpio, use BUSCARV para recuperar datos del catalogo. Sintaxis completa: =BUSCARV(valor_a_buscar, rango_de_la_tabla, numero_de_columna, 0). El 0 al final garantiza coincidencia exacta. El catalogo esta en otra hoja — use el nombre de hoja seguido de ! para referenciarlo. El numero de columna cambia segun lo que busque: nombre del producto es la columna 2, categoria es la 3, precio es la 4 y costo es la 5 del catalogo. TOTALES: Los totales de venta y costo se calculan multiplicando las unidades por el precio o costo unitario respectivamente. Bloquee con $ las referencias al catalogo para poder arrastrar la formula hacia abajo.
A17: # | B17: Mes | C17: Trim | D17: Sucursal | E17: Vendedor | F17: Cod. Original | G17: Cod. Limpio | H17: Nombre Producto | I17: Unidades | J17: Precio Unit. | K17: Costo Unit. | L17: Total Venta | M17: Total Costo
A18: 1 | B18: Enero | C18: T1 | D18: Central | E18: Juan Mora | F18: CON-001 | G18: =TRIM(F18) -> CON-001 | H18: =VLOOKUP($G18,Catalogo_Productos!$A$4:$E$33,2,0) -> Bloque 15x20x40 | I18: 45 | J18: =VLOOKUP($G18,Catalogo_Productos!$A$4:$E$33,4,0) -> 850 | K18: =VLOOKUP($G18,Catalogo_Productos!$A$4:$E$33,5,0) -> 510 | L18: =I18*J18 -> 38250 | M18: =I18*K18 -> 22950
A19: 2 | B19: Febrero | C19: T1 | D19: Cartago | E19: Luis Brenes | F19: PIN-002 | G19: =TRIM(F19) -> PIN-002 | H19: =VLOOKUP($G19,Catalogo_Productos!$A$4:$E$33,2,0) -> Sellador acrilico | I19: 11 | J19: =VLOOKUP($G19,Catalogo_Productos!$A$4:$E$33,4,0) -> 12000 | K19: =VLOOKUP($G19,Catalogo_Productos!$A$4:$E$33,5,0) -> 7200 | L19: =I19*J19 -> 132000 | M19: =I19*K19 -> 79200
A20: 3 | B20: Marzo | C20: T1 | D20: Heredia | E20: Fabiola Rios | F20: HER-003 | G20: =TRIM(F20) -> HER-003 | H20: =VLOOKUP($G20,Catalogo_Productos!$A$4:$E$33,2,0) -> Sierra circular 7in | I20: 42 | J20: =VLOOKUP($G20,Catalogo_Productos!$A$4:$E$33,4,0) -> 45000 | K20: =VLOOKUP($G20,Catalogo_Productos!$A$4:$E$33,5,0) -> 27000 | L20: =I20*J20 -> 1890000 | M20: =I20*K20 -> 1134000
A21: 4 | B21: Abril | C21: T2 | D21: Alajuela | E21: Rosa Mendez | F21: ELE-004 | G21: =TRIM(F21) -> ELE-004 | H21: =VLOOKUP($G21,Catalogo_Productos!$A$4:$E$33,2,0) -> Panel 12 circuitos | I21: 8 | J21: =VLOOKUP($G21,Catalogo_Productos!$A$4:$E$33,4,0) -> 38000 | K21: =VLOOKUP($G21,Catalogo_Productos!$A$4:$E$33,5,0) -> 22800 | L21: =I21*J21 -> 304000 | M21: =I21*K21 -> 182400
A22: 5 | B22: Mayo | C22: T2 | D22: Liberia | E22: Andres Mora | F22: PLO-005 | G22: =TRIM(F22) -> PLO-005 | H22: =VLOOKUP($G22,Catalogo_Productos!$A$4:$E$33,2,0) -> Llave de chorro | I22: 38 | J22: =VLOOKUP($G22,Catalogo_Productos!$A$4:$E$33,4,0) -> 8500 | K22: =VLOOKUP($G22,Catalogo_Productos!$A$4:$E$33,5,0) -> 5100 | L22: =I22*J22 -> 323000 | M22: =I22*K22 -> 193800
A23: 6 | B23: Junio | C23: T2 | D23: Central | E23: Ana Vargas | F23: CON-006 | G23: =TRIM(F23) -> CON-006 | H23: =VLOOKUP($G23,Catalogo_Productos!$A$4:$E$33,2,0) -> Regla aluminio 2m | I23: 3 | J23: =VLOOKUP($G23,Catalogo_Productos!$A$4:$E$33,4,0) -> 4500 | K23: =VLOOKUP($G23,Catalogo_Productos!$A$4:$E$33,5,0) -> 2700 | L23: =I23*J23 -> 13500 | M23: =I23*K23 -> 8100
A24: 7 | B24: Julio | C24: T3 | D24: Cartago | E24: Maria Jimenez | F24: PIN-001 | G24: =TRIM(F24) -> PIN-001 | H24: =VLOOKUP($G24,Catalogo_Productos!$A$4:$E$33,2,0) -> Pintura blanca 4L | I24: 6 | J24: =VLOOKUP($G24,Catalogo_Productos!$A$4:$E$33,4,0) -> 15500 | K24: =VLOOKUP($G24,Catalogo_Productos!$A$4:$E$33,5,0) -> 9300 | L24: =I24*J24 -> 93000 | M24: =I24*K24 -> 55800
A25: 8 | B25: Agosto | C25: T3 | D25: Heredia | E25: Pedro Quesada | F25: HER-002 | G25: =TRIM(F25) -> HER-002 | H25: =VLOOKUP($G25,Catalogo_Productos!$A$4:$E$33,2,0) -> Destornillador set x6 | I25: 22 | J25: =VLOOKUP($G25,Catalogo_Productos!$A$4:$E$33,4,0) -> 12000 | K25: =VLOOKUP($G25,Catalogo_Productos!$A$4:$E$33,5,0) -> 7200 | L25: =I25*J25 -> 264000 | M25: =I25*K25 -> 158400
A26: 9 | B26: Septiembre | C26: T3 | D26: Alajuela | E26: Patricia Salas | F26: ELE-003 | G26: =TRIM(F26) -> ELE-003 | H26: =VLOOKUP($G26,Catalogo_Productos!$A$4:$E$33,2,0) -> Breaker 20A | I26: 39 | J26: =VLOOKUP($G26,Catalogo_Productos!$A$4:$E$33,4,0) -> 7800 | K26: =VLOOKUP($G26,Catalogo_Productos!$A$4:$E$33,5,0) -> 4680 | L26: =I26*J26 -> 304200 | M26: =I26*K26 -> 182520
A27: 10 | B27: Octubre | C27: T4 | D27: Liberia | E27: Karina Solis | F27: PLO-004 | G27: =TRIM(F27) -> PLO-004 | H27: =VLOOKUP($G27,Catalogo_Productos!$A$4:$E$33,2,0) -> Sellador silicona | I27: 15 | J27: =VLOOKUP($G27,Catalogo_Productos!$A$4:$E$33,4,0) -> 3200 | K27: =VLOOKUP($G27,Catalogo_Productos!$A$4:$E$33,5,0) -> 1920 | L27: =I27*J27 -> 48000 | M27: =I27*K27 -> 28800
A28: 11 | B28: Noviembre | C28: T4 | D28: Central | E28: Carlos Solano | F28: CON-005 | G28: =TRIM(F28) -> CON-005 | H28: =VLOOKUP($G28,Catalogo_Productos!$A$4:$E$33,2,0) -> Malla electrosoldada | I28: 42 | J28: =VLOOKUP($G28,Catalogo_Productos!$A$4:$E$33,4,0) -> 15000 | K28: =VLOOKUP($G28,Catalogo_Productos!$A$4:$E$33,5,0) -> 9000 | L28: =I28*J28 -> 630000 | M28: =I28*K28 -> 378000
A29: 12 | B29: Diciembre | C29: T4 | D29: Cartago | E29: Sandra Vega | F29: PIN-006 | G29: =TRIM(F29) -> PIN-006 | H29: =VLOOKUP($G29,Catalogo_Productos!$A$4:$E$33,2,0) -> Brocha 4 pulgadas | I29: 23 | J29: =VLOOKUP($G29,Catalogo_Productos!$A$4:$E$33,4,0) -> 3200 | K29: =VLOOKUP($G29,Catalogo_Productos!$A$4:$E$33,5,0) -> 1920 | L29: =I29*J29 -> 73600 | M29: =I29*K29 -> 44160
... A107: 90 | B107: Junio | C107: T2 | D107: Liberia | E107: Karina Solis | F107: PLO-006 | G107: =TRIM(F107) -> PLO-006 | H107: =VLOOKUP($G107,Catalogo_Productos!$A$4:$E$33,2,0) -> Tee PVC 1/2 | I107: 18 | J107: =VLOOKUP($G107,Catalogo_Productos!$A$4:$E$33,4,0) -> 380 | K107: =VLOOKUP($G107,Catalogo_Productos!$A$4:$E$33,5,0) -> 228 | L107: =I107*J107 -> 6840 | M107: =I107*K107 -> 4104

Sheet Reto2_Logica
A1: RETO 2 — LOGICA CONDICIONAL: SI ANIDADO + SUMAR.SI.CONJUNTO + CONTAR.SI.CONJUNTO
A2: ENUNCIADO: Usando los totales de venta del Reto 1, clasifique cada transaccion: Premium (>= 500,000), Regular (200,000 a 499,999) o Basico (< 200,000). Luego construya una tabla resumen que muestre cuanto vende y cuantas transacciones tiene cada clasificacion por sucursal.
A4: PREGUNTAS DEL RETO 2
A5: R2-P1: Cuantas transacciones Premium tiene su version en total? Que porcentaje del total representan?
A6: Hay 8 transacciones Premium de las 90 registradas (8.9%). Su participación describe la frecuencia de compras de ₡500.000 o más en esta muestra.
A8: R2-P2: Cual sucursal concentra mas transacciones Basico? Proponga una hipotesis que explique por que podria estar ocurriendo eso.
A9: Liberia concentra 17 transacciones Básico de sus 18 registros. Una hipótesis es que su mezcla de productos o cantidades por compra favorezca tickets menores. Los datos no permiten atribuirlo al poder adquisitivo de sus clientes.
A11: R2-P3: Si la empresa quisiera mover transacciones de la categoria Basico a Regular, que estrategia operativa recomendaria?
A12: Para mover transacciones de Basico a Regular, la empresa podria implementar una estrategia de venta cruzada y empaques combinados (bundles) que incentiven al cliente a completar un monto minimo de compra, por ejemplo ofreciendo un descuento por volumen a partir de 200,000 colones. Tambien podria capacitar al equipo de ventas en tecnicas de upselling, sugiriendo productos complementarios al momento del cobro en las sucursales donde predominan las compras pequenas, como Liberia y Alajuela.
A15: COMO USAR SI ANIDADO: La funcion SI evalua una condicion y devuelve un valor si es verdadero y otro si es falso. Cuando necesita mas de dos categorias, anida una funcion SI dentro del argumento falso del SI anterior. Estructura general: =SI(condicion1, resultado1, SI(condicion2, resultado2, resultado_por_defecto)). El orden de las condiciones importa: empiece siempre por el umbral mas alto hacia el mas bajo. COMO USAR SUMAR.SI.CONJUNTO(): Suma celdas que cumplen multiples criterios simultaneamente. Sintaxis: =SUMAR.SI.CONJUNTO(rango_a_sumar, rango_criterio1, criterio1, rango_criterio2, criterio2). Para esta tabla necesita filtrar por sucursal Y por clasificacion al mismo tiempo. Use referencias absolutas ($) en los rangos para poder copiar la formula a las otras filas sin que se desplace. COMO USAR CONTAR.SI.CONJUNTO(): Igual que SUMAR.SI.CONJUNTO pero cuenta filas en lugar de sumar valores. Sintaxis: =CONTAR.SI.CONJUNTO(rango_criterio1, criterio1, rango_criterio2, criterio2).
A17: PARTE A — CLASIFICACION (SI ANIDADO)
A18: # | B18: Mes | C18: Trim | D18: Sucursal | E18: Vendedor | F18: Total Venta | G18: Clasificacion
A19: =Reto1_Datos!A18 -> 1 | B19: =Reto1_Datos!B18 -> Enero | C19: =Reto1_Datos!C18 -> T1 | D19: =Reto1_Datos!D18 -> Central | E19: =Reto1_Datos!E18 -> Juan Mora | F19: =Reto1_Datos!L18 -> 38250 | G19: =IF(F19>=500000,"Premium",IF(F19>=200000,"Regular","Basico")) -> Basico
A20: =Reto1_Datos!A19 -> 2 | B20: =Reto1_Datos!B19 -> Febrero | C20: =Reto1_Datos!C19 -> T1 | D20: =Reto1_Datos!D19 -> Cartago | E20: =Reto1_Datos!E19 -> Luis Brenes | F20: =Reto1_Datos!L19 -> 132000 | G20: =IF(F20>=500000,"Premium",IF(F20>=200000,"Regular","Basico")) -> Basico
A21: =Reto1_Datos!A20 -> 3 | B21: =Reto1_Datos!B20 -> Marzo | C21: =Reto1_Datos!C20 -> T1 | D21: =Reto1_Datos!D20 -> Heredia | E21: =Reto1_Datos!E20 -> Fabiola Rios | F21: =Reto1_Datos!L20 -> 1890000 | G21: =IF(F21>=500000,"Premium",IF(F21>=200000,"Regular","Basico")) -> Premium
A22: =Reto1_Datos!A21 -> 4 | B22: =Reto1_Datos!B21 -> Abril | C22: =Reto1_Datos!C21 -> T2 | D22: =Reto1_Datos!D21 -> Alajuela | E22: =Reto1_Datos!E21 -> Rosa Mendez | F22: =Reto1_Datos!L21 -> 304000 | G22: =IF(F22>=500000,"Premium",IF(F22>=200000,"Regular","Basico")) -> Regular
A23: =Reto1_Datos!A22 -> 5 | B23: =Reto1_Datos!B22 -> Mayo | C23: =Reto1_Datos!C22 -> T2 | D23: =Reto1_Datos!D22 -> Liberia | E23: =Reto1_Datos!E22 -> Andres Mora | F23: =Reto1_Datos!L22 -> 323000 | G23: =IF(F23>=500000,"Premium",IF(F23>=200000,"Regular","Basico")) -> Regular
A24: =Reto1_Datos!A23 -> 6 | B24: =Reto1_Datos!B23 -> Junio | C24: =Reto1_Datos!C23 -> T2 | D24: =Reto1_Datos!D23 -> Central | E24: =Reto1_Datos!E23 -> Ana Vargas | F24: =Reto1_Datos!L23 -> 13500 | G24: =IF(F24>=500000,"Premium",IF(F24>=200000,"Regular","Basico")) -> Basico
A25: =Reto1_Datos!A24 -> 7 | B25: =Reto1_Datos!B24 -> Julio | C25: =Reto1_Datos!C24 -> T3 | D25: =Reto1_Datos!D24 -> Cartago | E25: =Reto1_Datos!E24 -> Maria Jimenez | F25: =Reto1_Datos!L24 -> 93000 | G25: =IF(F25>=500000,"Premium",IF(F25>=200000,"Regular","Basico")) -> Basico
A26: =Reto1_Datos!A25 -> 8 | B26: =Reto1_Datos!B25 -> Agosto | C26: =Reto1_Datos!C25 -> T3 | D26: =Reto1_Datos!D25 -> Heredia | E26: =Reto1_Datos!E25 -> Pedro Quesada | F26: =Reto1_Datos!L25 -> 264000 | G26: =IF(F26>=500000,"Premium",IF(F26>=200000,"Regular","Basico")) -> Regular
A27: =Reto1_Datos!A26 -> 9 | B27: =Reto1_Datos!B26 -> Septiembre | C27: =Reto1_Datos!C26 -> T3 | D27: =Reto1_Datos!D26 -> Alajuela | E27: =Reto1_Datos!E26 -> Patricia Salas | F27: =Reto1_Datos!L26 -> 304200 | G27: =IF(F27>=500000,"Premium",IF(F27>=200000,"Regular","Basico")) -> Regular
A28: =Reto1_Datos!A27 -> 10 | B28: =Reto1_Datos!B27 -> Octubre | C28: =Reto1_Datos!C27 -> T4 | D28: =Reto1_Datos!D27 -> Liberia | E28: =Reto1_Datos!E27 -> Karina Solis | F28: =Reto1_Datos!L27 -> 48000 | G28: =IF(F28>=500000,"Premium",IF(F28>=200000,"Regular","Basico")) -> Basico
A29: =Reto1_Datos!A28 -> 11 | B29: =Reto1_Datos!B28 -> Noviembre | C29: =Reto1_Datos!C28 -> T4 | D29: =Reto1_Datos!D28 -> Central | E29: =Reto1_Datos!E28 -> Carlos Solano | F29: =Reto1_Datos!L28 -> 630000 | G29: =IF(F29>=500000,"Premium",IF(F29>=200000,"Regular","Basico")) -> Premium
A30: =Reto1_Datos!A29 -> 12 | B30: =Reto1_Datos!B29 -> Diciembre | C30: =Reto1_Datos!C29 -> T4 | D30: =Reto1_Datos!D29 -> Cartago | E30: =Reto1_Datos!E29 -> Sandra Vega | F30: =Reto1_Datos!L29 -> 73600 | G30: =IF(F30>=500000,"Premium",IF(F30>=200000,"Regular","Basico")) -> Basico
... A108: =Reto1_Datos!A107 -> 90 | B108: =Reto1_Datos!B107 -> Junio | C108: =Reto1_Datos!C107 -> T2 | D108: =Reto1_Datos!D107 -> Liberia | E108: =Reto1_Datos!E107 -> Karina Solis | F108: =Reto1_Datos!L107 -> 6840 | G108: =IF(F108>=500000,"Premium",IF(F108>=200000,"Regular","Basico")) -> Basico
A110: PARTE B — TABLA RESUMEN POR SUCURSAL
A111: Sucursal | B111: Clasificacion | C111: Total Ventas | D111: N Transacciones
A112: Central | B112: Premium | C112: =SUMIFS($F$19:$F$108,$D$19:$D$108,$A112,$G$19:$G$108,$B112) -> 630000 | D112: =COUNTIFS($D$19:$D$108,$A112,$G$19:$G$108,$B112) -> 1
A113: Central | B113: Regular | C113: =SUMIFS($F$19:$F$108,$D$19:$D$108,$A113,$G$19:$G$108,$B113) -> 1994500 | D113: =COUNTIFS($D$19:$D$108,$A113,$G$19:$G$108,$B113) -> 5
A114: Central | B114: Basico | C114: =SUMIFS($F$19:$F$108,$D$19:$D$108,$A114,$G$19:$G$108,$B114) -> 722300 | D114: =COUNTIFS($D$19:$D$108,$A114,$G$19:$G$108,$B114) -> 12
A116: Cartago | B116: Premium | C116: =SUMIFS($F$19:$F$108,$D$19:$D$108,$A116,$G$19:$G$108,$B116) -> 697500 | D116: =COUNTIFS($D$19:$D$108,$A116,$G$19:$G$108,$B116) -> 1
A117: Cartago | B117: Regular | C117: =SUMIFS($F$19:$F$108,$D$19:$D$108,$A117,$G$19:$G$108,$B117) -> 2051400 | D117: =COUNTIFS($D$19:$D$108,$A117,$G$19:$G$108,$B117) -> 5
A118: Cartago | B118: Basico | C118: =SUMIFS($F$19:$F$108,$D$19:$D$108,$A118,$G$19:$G$108,$B118) -> 1048300 | D118: =COUNTIFS($D$19:$D$108,$A118,$G$19:$G$108,$B118) -> 12
A120: Heredia | B120: Premium | C120: =SUMIFS($F$19:$F$108,$D$19:$D$108,$A120,$G$19:$G$108,$B120) -> 9115000 | D120: =COUNTIFS($D$19:$D$108,$A120,$G$19:$G$108,$B120) -> 5
A121: Heredia | B121: Regular | C121: =SUMIFS($F$19:$F$108,$D$19:$D$108,$A121,$G$19:$G$108,$B121) -> 1172200 | D121: =COUNTIFS($D$19:$D$108,$A121,$G$19:$G$108,$B121) -> 4
A122: Heredia | B122: Basico | C122: =SUMIFS($F$19:$F$108,$D$19:$D$108,$A122,$G$19:$G$108,$B122) -> 916900 | D122: =COUNTIFS($D$19:$D$108,$A122,$G$19:$G$108,$B122) -> 9
A124: Alajuela | B124: Premium | C124: =SUMIFS($F$19:$F$108,$D$19:$D$108,$A124,$G$19:$G$108,$B124) -> 1520000 | D124: =COUNTIFS($D$19:$D$108,$A124,$G$19:$G$108,$B124) -> 1
A125: Alajuela | B125: Regular | C125: =SUMIFS($F$19:$F$108,$D$19:$D$108,$A125,$G$19:$G$108,$B125) -> 1450400 | D125: =COUNTIFS($D$19:$D$108,$A125,$G$19:$G$108,$B125) -> 5
A126: Alajuela | B126: Basico | C126: =SUMIFS($F$19:$F$108,$D$19:$D$108,$A126,$G$19:$G$108,$B126) -> 604100 | D126: =COUNTIFS($D$19:$D$108,$A126,$G$19:$G$108,$B126) -> 12
... A130: Liberia | B130: Basico | C130: =SUMIFS($F$19:$F$108,$D$19:$D$108,$A130,$G$19:$G$108,$B130) -> 893700 | D130: =COUNTIFS($D$19:$D$108,$A130,$G$19:$G$108,$B130) -> 17

Sheet Reto3_Estadisticas
A1: RETO 3 — ESTADISTICAS DESCRIPTIVAS POR SUCURSAL
A2: ENUNCIADO: Calcule las estadisticas descriptivas de las ventas totales por transaccion, agrupadas por sucursal. Estas estadisticas le permitiran comparar el desempeno de las cinco sucursales e identificar patrones relevantes para la toma de decisiones.
A4: Sucursal | B4: PROMEDIO | C4: MEDIANA | D4: MAXIMO | E4: MINIMO | F4: DESV. EST. | G4: N TRANS.
A5: Central | B5: =AVERAGEIFS(Reto1_Datos!$L$18:$L$107,Reto1_Datos!$D$18:$D$107,A5) -> 185933.33 | C5: {=MEDIAN(IF(Reto1_Datos!$D$18:$D$107=A5,Reto1_Datos!$L$18:$L$107))} -> 82000 | D5: =_xlfn.MAXIFS(Reto1_Datos!$L$18:$L$107,Reto1_Datos!$D$18:$D$107,A5) -> 630000 | E5: =_xlfn.MINIFS(Reto1_Datos!$L$18:$L$107,Reto1_Datos!$D$18:$D$107,A5) -> 7650 | F5: {=STDEV(IF(Reto1_Datos!$D$18:$D$107=A5,Reto1_Datos!$L$18:$L$107))} -> 199186.3 | G5: =COUNTIF(Reto1_Datos!$D$18:$D$107,A5) -> 18
A6: Cartago | B6: =AVERAGEIFS(Reto1_Datos!$L$18:$L$107,Reto1_Datos!$D$18:$D$107,A6) -> 210955.56 | C6: {=MEDIAN(IF(Reto1_Datos!$D$18:$D$107=A6,Reto1_Datos!$L$18:$L$107))} -> 135750 | D6: =_xlfn.MAXIFS(Reto1_Datos!$L$18:$L$107,Reto1_Datos!$D$18:$D$107,A6) -> 697500 | E6: =_xlfn.MINIFS(Reto1_Datos!$L$18:$L$107,Reto1_Datos!$D$18:$D$107,A6) -> 16000 | F6: {=STDEV(IF(Reto1_Datos!$D$18:$D$107=A6,Reto1_Datos!$L$18:$L$107))} -> 197711.78 | G6: =COUNTIF(Reto1_Datos!$D$18:$D$107,A6) -> 18
A7: Heredia | B7: =AVERAGEIFS(Reto1_Datos!$L$18:$L$107,Reto1_Datos!$D$18:$D$107,A7) -> 622450 | C7: {=MEDIAN(IF(Reto1_Datos!$D$18:$D$107=A7,Reto1_Datos!$L$18:$L$107))} -> 198000 | D7: =_xlfn.MAXIFS(Reto1_Datos!$L$18:$L$107,Reto1_Datos!$D$18:$D$107,A7) -> 2860000 | E7: =_xlfn.MINIFS(Reto1_Datos!$L$18:$L$107,Reto1_Datos!$D$18:$D$107,A7) -> 24000 | F7: {=STDEV(IF(Reto1_Datos!$D$18:$D$107=A7,Reto1_Datos!$L$18:$L$107))} -> 854389.08 | G7: =COUNTIF(Reto1_Datos!$D$18:$D$107,A7) -> 18
A8: Alajuela | B8: =AVERAGEIFS(Reto1_Datos!$L$18:$L$107,Reto1_Datos!$D$18:$D$107,A8) -> 198583.33 | C8: {=MEDIAN(IF(Reto1_Datos!$D$18:$D$107=A8,Reto1_Datos!$L$18:$L$107))} -> 78900 | D8: =_xlfn.MAXIFS(Reto1_Datos!$L$18:$L$107,Reto1_Datos!$D$18:$D$107,A8) -> 1520000 | E8: =_xlfn.MINIFS(Reto1_Datos!$L$18:$L$107,Reto1_Datos!$D$18:$D$107,A8) -> 8400 | F8: {=STDEV(IF(Reto1_Datos!$D$18:$D$107=A8,Reto1_Datos!$L$18:$L$107))} -> 350489.16 | G8: =COUNTIF(Reto1_Datos!$D$18:$D$107,A8) -> 18
A9: Liberia | B9: =AVERAGEIFS(Reto1_Datos!$L$18:$L$107,Reto1_Datos!$D$18:$D$107,A9) -> 67594.444 | C9: {=MEDIAN(IF(Reto1_Datos!$D$18:$D$107=A9,Reto1_Datos!$L$18:$L$107))} -> 46000 | D9: =_xlfn.MAXIFS(Reto1_Datos!$L$18:$L$107,Reto1_Datos!$D$18:$D$107,A9) -> 323000 | E9: =_xlfn.MINIFS(Reto1_Datos!$L$18:$L$107,Reto1_Datos!$D$18:$D$107,A9) -> 900 | F9: {=STDEV(IF(Reto1_Datos!$D$18:$D$107=A9,Reto1_Datos!$L$18:$L$107))} -> 80978.511 | G9: =COUNTIF(Reto1_Datos!$D$18:$D$107,A9) -> 18
A11: COMO CALCULAR ESTADISTICAS POR GRUPO: En Excel existen dos enfoques. Opcion A (mas sencilla en Excel 365): use las variantes .SI.CONJUNTO de las funciones estadisticas. Por ejemplo, PROMEDIO.SI.CONJUNTO(rango_de_valores, rango_de_criterio, valor_del_criterio) promedia solo las filas donde el criterio coincide. Opcion B (Excel 2016): use formulas matriciales — ingrese =PROMEDIO(SI(rango_sucursal=criterio, rango_valores)) y confirme con Ctrl+Shift+Enter en lugar de solo Enter. LAS SEIS FUNCIONES REQUERIDAS: PROMEDIO (media aritmetica), MEDIANA (valor central al ordenar), MAX (mayor valor), MIN (menor valor), DESVEST (variabilidad), CONTAR (cantidad de filas). Cada una acepta un rango como argumento. La clave es que ese rango filtre solo las filas de la sucursal correcta. INTERPRETACION: La desviacion estandar mide que tan dispersas estan las ventas alrededor del promedio. Una desviacion alta significa que hay transacciones muy grandes junto a transacciones muy pequeñas.
A13: PREGUNTAS DE ANALISIS DEL RETO 3
A14: R3-P1: Cual sucursal tiene el promedio mas alto? Cual el mas bajo? Que diferencia hay entre ambas en terminos absolutos y porcentuales?
A15: Heredia tiene el promedio más alto: ₡622.450 por transacción. Liberia tiene el menor: ₡67.594. La diferencia es de ₡554.856; Heredia equivale a 9,21 veces Liberia, aproximadamente un 820,9% más.
A17: R3-P2: Encuentre una sucursal donde la mediana sea notablemente diferente al promedio. Que le indica esa diferencia sobre la distribucion de las ventas en esa sucursal?
A18: Heredia es la sucursal donde la mediana (198,000) es notablemente mas baja que el promedio (622,450). Esa diferencia tan marcada indica que la distribucion de ventas de Heredia esta sesgada hacia la derecha: existen unas pocas transacciones muy grandes (el maximo llega a 2,860,000) que arrastran el promedio hacia arriba, mientras que la mitad de sus transacciones son de 198,000 colones o menos. En otras palabras, el desempeno de Heredia depende de pocas ventas excepcionalmente grandes y no de un flujo uniforme de ventas medianas.
A20: R3-P3: Cual sucursal tiene la desviacion estandar mas alta? Que significa eso para la predictibilidad de sus ventas mes a mes?
A21: Heredia presenta la mayor desviación estándar por transacción: ₡854.389. Esto indica alta dispersión entre compras individuales. Para evaluar la estabilidad mes a mes es necesario agregar las ventas por mes; esta estadística por transacción no demuestra por sí sola la predictibilidad mensual.
A23: R3-P4: Con base en estas estadisticas, cual sucursal elegiria para un piloto de programa de incentivos de ventas? Justifique con al menos dos indicadores numericos.
A24: Propondría Cartago para un piloto: su promedio por transacción es ₡210.956, su mediana ₡135.750 y su desviación estándar ₡197.712, menor que la de Heredia (₡854.389). Es una propuesta que requiere un grupo de comparación y medición antes y después; estas cifras no garantizan estabilidad mensual ni el efecto del incentivo.

Sheet Reto4_TablaDin
A1: RETO 4 — TABLA DINAMICA CON CAMPO CALCULADO Y SEGMENTADOR
A2: ENUNCIADO: Con los datos de esta hoja construya una tabla dinamica que cruce sucursal (filas) con categoria (columnas) mostrando la suma de ventas. Agregue un campo calculado llamado Margen = (Total Venta - Total Costo) / Total Venta y un segmentador por Trimestre.
A4: PASOS PARA CREAR LA TABLA DINAMICA: Paso 1 — Seleccione todo el rango de datos de esta hoja incluyendo los encabezados. Paso 2 — Vaya a Insertar > Tabla dinamica. En el cuadro de dialogo, elija "Hoja de calculo existente" y haga clic en la celda donde quiere ubicarla (por ejemplo M1 de esta misma hoja). Paso 3 — En el panel de campos: arrastre Sucursal a Filas, Categoria a Columnas, y Total Venta a Valores. Verifique que el campo de valores diga "Suma de Total Venta" (no promedio ni conteo). Paso 4 — Para el campo calculado: en la cinta superior, con la tabla dinamica seleccionada, vaya a Analisis > Campos, elementos y conjuntos > Campo calculado. Escriba el nombre "Margen" y en la formula ingrese los nombres de campo tal como aparecen en la lista inferior del cuadro de dialogo. La formula calcula la diferencia entre venta y costo dividida entre la venta total. Aplique formato de porcentaje. Paso 5 — Para el segmentador: Analisis > Insertar segmentador > seleccione Trimestre. Al hacer clic en T1, T2, T3 o T4, la tabla filtrara automaticamente.
A6: # | B6: Mes | C6: Trim | D6: Sucursal | E6: Categoria | F6: Vendedor | G6: Nombre Producto | H6: Unidades | I6: Precio Unit. | J6: Total Venta | K6: Total Costo | S6: Column Labels
A7: 1 | B7: Enero | C7: T1 | D7: Central | E7: Construccion | F7: Juan Mora | G7: Bloque 15x20x40 | H7: 45 | I7: 898 | J7: 40410 | K7: 24210 | S7: Construccion | U7: Electricos | W7: Herramientas | Y7: Pintura | AA7: Plomeria | AC7: Total Sum of Total Venta | AD7: Total Sum of margen
A8: 2 | B8: Febrero | C8: T1 | D8: Cartago | E8: Pintura | F8: Luis Brenes | G8: Sellador acrilico | H8: 11 | I8: 11423 | J8: 125653 | K8: 75383 | R8: Row Labels | S8: Sum of Total Venta | T8: Sum of margen | U8: Sum of Total Venta | V8: Sum of margen | W8: Sum of Total Venta | X8: Sum of margen | Y8: Sum of Total Venta | Z8: Sum of margen | AA8: Sum of Total Venta | AB8: Sum of margen
A9: 3 | B9: Marzo | C9: T1 | D9: Heredia | E9: Herramientas | F9: Fabiola Rios | G9: Sierra circular 7in | H9: 42 | I9: 48144 | J9: 2022048 | K9: 1213212 | R9: Alajuela | T9: n.a. | U9: 3497247 | V9: 0.40004552 | X9: n.a. | Z9: n.a. | AB9: n.a. | AC9: 3497247 | AD9: 0.40004552
A10: 4 | B10: Abril | C10: T2 | D10: Alajuela | E10: Electricos | F10: Rosa Mendez | G10: Panel 12 circuitos | H10: 8 | I10: 40828 | J10: 326624 | K10: 195968 | R10: Cartago | T10: n.a. | V10: n.a. | X10: n.a. | Y10: 3808403 | Z10: 0.40003881 | AB10: n.a. | AC10: 3808403 | AD10: 0.40003881
A11: 5 | B11: Mayo | C11: T2 | D11: Liberia | E11: Plomeria | F11: Andres Mora | G11: Llave de chorro | H11: 38 | I11: 9189 | J11: 349182 | K11: 209494 | R11: Central | S11: 3394020 | T11: 0.40005097 | V11: n.a. | X11: n.a. | Z11: n.a. | AB11: n.a. | AC11: 3394020 | AD11: 0.40005097
A12: 6 | B12: Junio | C12: T2 | D12: Central | E12: Construccion | F12: Ana Vargas | G12: Regla aluminio 2m | H12: 3 | I12: 4420 | J12: 13260 | K12: 7956 | R12: Heredia | T12: n.a. | V12: n.a. | W12: 11357109 | X12: 0.4000217 | Z12: n.a. | AB12: n.a. | AC12: 11357109 | AD12: 0.4000217
A13: 7 | B13: Julio | C13: T3 | D13: Cartago | E13: Pintura | F13: Maria Jimenez | G13: Pintura blanca 4L | H13: 6 | I13: 14270 | J13: 85620 | K13: 51372 | R13: Liberia | T13: n.a. | V13: n.a. | X13: n.a. | Z13: n.a. | AA13: 1230944 | AB13: 0.40013031 | AC13: 1230944 | AD13: 0.40013031
A14: 8 | B14: Agosto | C14: T3 | D14: Heredia | E14: Herramientas | F14: Pedro Quesada | G14: Destornillador set x6 | H14: 22 | I14: 11938 | J14: 262636 | K14: 157564 | R14: Grand Total | S14: 3394020 | T14: 0.40005097 | U14: 3497247 | V14: 0.40004552 | W14: 11357109 | X14: 0.4000217 | Y14: 3808403 | Z14: 0.40003881 | AA14: 1230944 | AB14: 0.40013031 | AC14: 23287723 | AD14: 0.40003808
A15: 9 | B15: Septiembre | C15: T3 | D15: Alajuela | E15: Electricos | F15: Patricia Salas | G15: Breaker 20A | H15: 39 | I15: 7721 | J15: 301119 | K15: 180648
A16: 10 | B16: Octubre | C16: T4 | D16: Liberia | E16: Plomeria | F16: Karina Solis | G16: Sellador silicona | H16: 15 | I16: 3007 | J16: 45105 | K16: 27060
A17: 11 | B17: Noviembre | C17: T4 | D17: Central | E17: Construccion | F17: Carlos Solano | G17: Malla electrosoldada | H17: 42 | I17: 16225 | J17: 681450 | K17: 408870
A18: 12 | B18: Diciembre | C18: T4 | D18: Cartago | E18: Pintura | F18: Sandra Vega | G18: Brocha 4 pulgadas | H18: 23 | I18: 3090 | J18: 71070 | K18: 42642
A19: 13 | B19: Enero | C19: T1 | D19: Heredia | E19: Herramientas | F19: Diana Castro | G19: Martillo 500g | H19: 7 | I19: 8717 | J19: 61019 | K19: 36610
A20: 14 | B20: Febrero | C20: T1 | D20: Alajuela | E20: Electricos | F20: Fabio Ulate | G20: Tomacorriente doble | H20: 33 | I20: 4120 | J20: 135960 | K20: 81576
A21: 15 | B21: Marzo | C21: T1 | D21: Liberia | E21: Plomeria | F21: Andres Mora | G21: Codo 90 PVC 1/2 | H21: 15 | I21: 456 | J21: 6840 | K21: 4095
A22: 16 | B22: Abril | C22: T2 | D22: Central | E22: Construccion | F22: Rita Ulate | G22: Arena (m3) | H22: 4 | I22: 11284 | J22: 45136 | K22: 27080
A23: 17 | B23: Mayo | C23: T2 | D23: Cartago | E23: Pintura | F23: Luis Brenes | G23: Rodillo de esponja | H23: 7 | I23: 4221 | J23: 29547 | K23: 17724
A24: 18 | B24: Junio | C24: T2 | D24: Heredia | E24: Herramientas | F24: Fabiola Rios | G24: Nivel de burbuja 60cm | H24: 20 | I24: 7495 | J24: 149900 | K24: 89940
A25: 19 | B25: Julio | C25: T3 | D25: Alajuela | E25: Electricos | F25: Rosa Mendez | G25: Cable THHN #12 (m) | H25: 18 | I25: 792 | J25: 14256 | K25: 8550
A26: 20 | B26: Agosto | C26: T3 | D26: Liberia | E26: Plomeria | F26: Karina Solis | G26: Llave de paso 1/2 | H26: 9 | I26: 5946 | J26: 53514 | K26: 32103
... A30: 24 | B30: Diciembre | C30: T4 | D30: Alajuela | E30: Electricos | F30: Patricia Salas | G30: Interruptor sencillo | H30: 43 | I30: 2865 | J30: 123195 | K30: 73917
A31: 25 | B31: Enero | C31: T1 | D31: Liberia | E31: Plomeria | F31: Andres Mora | G31: Tubo PVC 1/2 (6m) | H31: 19 | I31: 3338 | J31: 63422 | K31: 38038 | R31: n.a.: margen no aplicable cuando no hay ventas en la combinación filtrada.
A32: 26 | B32: Febrero | C32: T1 | D32: Central | E32: Construccion | F32: Ana Vargas | G32: Cemento 50kg | H32: 43 | I32: 8220 | J32: 353460 | K32: 212076
A33: 27 | B33: Marzo | C33: T1 | D33: Cartago | E33: Pintura | F33: Sandra Vega | G33: Thinner industrial | H33: 30 | I33: 10596 | J33: 317880 | K33: 190710
A34: 28 | B34: Abril | C34: T2 | D34: Heredia | E34: Herramientas | F34: Diana Castro | G34: Cinta metrica 5m | H34: 42 | I34: 3341 | J34: 140322 | K34: 84168
A35: 29 | B35: Mayo | C35: T2 | D35: Alajuela | E35: Electricos | F35: Fabio Ulate | G35: Cinta aislante | H35: 29 | I35: 884 | J35: 25636 | K35: 15370
A36: 30 | B36: Junio | C36: T2 | D36: Liberia | E36: Plomeria | F36: Karina Solis | G36: Tee PVC 1/2 | H36: 27 | I36: 412 | J36: 11124 | K36: 6669
A37: 31 | B37: Julio | C37: T3 | D37: Central | E37: Construccion | F37: Carlos Solano | G37: Bloque 15x20x40 | H37: 9 | I37: 882 | J37: 7938 | K37: 4761
A38: 32 | B38: Agosto | C38: T3 | D38: Cartago | E38: Pintura | F38: Luis Brenes | G38: Sellador acrilico | H38: 39 | I38: 11828 | J38: 461292 | K38: 276744
A39: 33 | B39: Septiembre | C39: T3 | D39: Heredia | E39: Herramientas | F39: Fabiola Rios | G39: Sierra circular 7in | H39: 16 | I39: 41547 | J39: 664752 | K39: 398848
A40: 34 | B40: Octubre | C40: T4 | D40: Alajuela | E40: Electricos | F40: Rosa Mendez | G40: Panel 12 circuitos | H40: 40 | I40: 34593 | J40: 1383720 | K40: 830200
A41: 35 | B41: Noviembre | C41: T4 | D41: Liberia | E41: Plomeria | F41: Andres Mora | G41: Llave de chorro | H41: 14 | I41: 8391 | J41: 117474 | K41: 70476
A42: 36 | B42: Diciembre | C42: T4 | D42: Central | E42: Construccion | F42: Rita Ulate | G42: Regla aluminio 2m | H42: 13 | I42: 4805 | J42: 62465 | K42: 37479
A43: 37 | B43: Enero | C43: T1 | D43: Cartago | E43: Pintura | F43: Maria Jimenez | G43: Pintura blanca 4L | H43: 9 | I43: 16380 | J43: 147420 | K43: 88452
... A96: 90 | B96: Junio | C96: T2 | D96: Liberia | E96: Plomeria | F96: Karina Solis | G96: Tee PVC 1/2 | H96: 18 | I96: 342 | J96: 6156 | K96: 3690
A99: PREGUNTAS DEL RETO 4
...

Sheet Reto5_Financiero
A1: RETO 5 — ANALISIS FINANCIERO: PAGO, VAN Y TIR
A2: ENUNCIADO: La gerencia de Ferreteria Los Robles evalua dos decisiones financieras: (A) un credito para ampliar la bodega central y (B) un proyecto de inversion en vehiculos de reparto propio. Use PAGO, VAN y TIR para analizar la viabilidad de cada decision y emitir una recomendacion justificada.
A4: PARTE A — CREDITO PARA EXPANSION DE BODEGA
A5: PAGO(tasa, nper, va) calcula una cuota periódica constante. La tasa y el plazo deben usar la misma unidad. En este ejercicio se usa -monto como valor actual para mostrar la cuota como un importe positivo; los signos representan sentidos opuestos del flujo.
A7: Monto del credito (colones) | B7: 20000000
A8: Tasa de interes mensual | B8: 0.012
A9: Plazo (meses) | B9: 48
A11: R5-P1: Calcule la cuota mensual con PAGO. Cuanto paga el negocio cada mes por este credito?
A12: Cuota mensual = | B12: =PMT(B8,B9,-B7) -> 550551.04
A13: R5-P2: El flujo de caja mensual disponible de la empresa es de 650,000 colones. Puede asumir esta cuota? Cuanto queda libre despues de pagarla? Calcule tambien el total pagado en los 48 meses.
A14: Con una cuota mensual de 550,551 colones y un flujo de caja disponible de 650,000 colones, la empresa si puede asumir el credito: le quedarian 99,449 colones libres cada mes despues de pagar la cuota, un margen de maniobra de apenas 15.3% sobre el flujo disponible, por lo que conviene monitorear de cerca cualquier caida en las ventas. En total, a lo largo de los 48 meses el negocio pagaria 26,426,450 colones, es decir 6,426,450 colones mas que el monto original del prestamo, que corresponden al costo financiero (intereses) del credito.
A16: PARTE B — PROYECTO DE INVERSION: VEHICULOS DE REPARTO (VAN y TIR)
A17: COMO USAR VNA(): Calcula el Valor Actual Neto de una serie de flujos futuros. Sintaxis: =VNA(tasa, rango_de_flujos_futuros). Importante: VNA NO incluye la inversion inicial — esta debe sumarse por separado porque ocurre en el periodo 0. La formula completa es: =VNA(tasa_descuento, flujos_futuros) + inversion_inicial. Si la inversion esta con signo negativo en una celda, sumela directamente. COMO USAR TIR(): Calcula la tasa interna de retorno a partir de una serie de flujos que incluye la inversion inicial con signo negativo. Sintaxis: =TIR(rango_completo_de_flujos). El primer valor del rango debe ser la inversion inicial (negativo) seguida de los flujos positivos de cada periodo. INTERPRETACION: Si el VAN es positivo, el proyecto genera valor por encima de la tasa de descuento exigida. La TIR es la tasa a la que el proyecto exactamente recupera la inversion — si TIR > tasa de descuento, el proyecto es viable.
A19: Tasa de descuento anual | B19: 0.14
B21: Escenario Conservador | E21: Escenario Optimista
A22: Inversion inicial (negativa): | B22: -9000000 | E22: -9000000
A23: Flujo Anio 1: | B23: 2339951 | E23: 3436339
A24: Flujo Anio 2: | B24: 2059930 | E24: 2925426
A25: Flujo Anio 3: | B25: 1997811 | E25: 2799499
A26: Flujo Anio 4: | B26: 2791223 | E26: 3736715
A27: Flujo Anio 5: | B27: 2799208 | E27: 3623697
A29: VAN del proyecto: | B29: =NPV(B19,B23:B27)+B22 -> -907447.63 | E29: =NPV(B19,E23:E27)+E22 -> 2249404.8
A30: TIR del proyecto: | B30: =IRR(B22:B27) -> 0.098965582 | E30: =IRR(E22:E27) -> 0.23782965
A32: R5-P3: En cual de los dos escenarios es viable la inversion? Como lo determina usando el VAN y la TIR? Que sucede si el VAN es negativo — significa que el proyecto pierde dinero o que no alcanza la rentabilidad esperada?
A33: El proyecto solo es viable en el escenario optimista. En el escenario conservador el VAN es negativo (-907,448 colones) y la TIR (9.90%) queda por debajo de la tasa de descuento exigida del 14%, lo que significa que los flujos proyectados no alcanzan a cubrir el costo del dinero en el tiempo: el proyecto destruye valor en ese escenario. En el escenario optimista el VAN es positivo (2,249,405 colones) y la TIR (23.78%) supera ampliamente el 14% exigido, por lo que si conviene invertir. Un VAN negativo no significa necesariamente que el proyecto pierda dinero en terminos contables, sino que no alcanza a rendir lo minimo que la empresa exige (la tasa de descuento) despues de considerar el valor del dinero en el tiempo.
A34: R5-P4: Si la tasa mensual del credito de la Parte A subiera al 1.8%, cuanto cambiaria la cuota? Calcule la diferencia en colones y en porcentaje. Es un cambio significativo para el negocio?
A35: Al subir la tasa mensual del 1,2% al 1,8%, la cuota pasa de ₡550,551 a ₡625,786: aumenta ₡75,235 (13.67%). Con ₡650.000 disponibles quedarían ₡24,214 al mes. El cálculo mantiene el plazo de 48 meses y no incluye comisiones ni seguros.

Sheet Reto6_Dashboard
A1: RETO 6 — DASHBOARD EJECUTIVO Y ANALISIS GRUPAL
A2: ENUNCIADO: Construya dos graficos estrategicos con los datos pre-calculados de esta hoja y responda las cuatro preguntas de analisis. Nota: el analisis escrito INDIVIDUAL es un documento separado — ver hoja Analisis_Individual.
A4: TABLA 1 — VENTAS POR SUCURSAL Y TRIMESTRE (BASE RETO 1)
A5: Sucursal | B5: T1 | C5: T2 | D5: T3 | E5: T4 | F5: TOTAL
A6: Central | B6: =SUMIFS(Reto1_Datos!$L$18:$L$107,Reto1_Datos!$D$18:$D$107,$A6,Reto1_Datos!$C$18:$C$107,B$5) -> 793050 | C6: =SUMIFS(Reto1_Datos!$L$18:$L$107,Reto1_Datos!$D$18:$D$107,$A6,Reto1_Datos!$C$18:$C$107,C$5) -> 1155000 | D6: =SUMIFS(Reto1_Datos!$L$18:$L$107,Reto1_Datos!$D$18:$D$107,$A6,Reto1_Datos!$C$18:$C$107,D$5) -> 149250 | E6: =SUMIFS(Reto1_Datos!$L$18:$L$107,Reto1_Datos!$D$18:$D$107,$A6,Reto1_Datos!$C$18:$C$107,E$5) -> 1249500 | F6: =SUM(B6:E6) -> 3346800
A7: Cartago | B7: =SUMIFS(Reto1_Datos!$L$18:$L$107,Reto1_Datos!$D$18:$D$107,$A7,Reto1_Datos!$C$18:$C$107,B$5) -> 1142900 | C7: =SUMIFS(Reto1_Datos!$L$18:$L$107,Reto1_Datos!$D$18:$D$107,$A7,Reto1_Datos!$C$18:$C$107,C$5) -> 207000 | D7: =SUMIFS(Reto1_Datos!$L$18:$L$107,Reto1_Datos!$D$18:$D$107,$A7,Reto1_Datos!$C$18:$C$107,D$5) -> 1405500 | E7: =SUMIFS(Reto1_Datos!$L$18:$L$107,Reto1_Datos!$D$18:$D$107,$A7,Reto1_Datos!$C$18:$C$107,E$5) -> 1041800 | F7: =SUM(B7:E7) -> 3797200
A8: Heredia | B8: =SUMIFS(Reto1_Datos!$L$18:$L$107,Reto1_Datos!$D$18:$D$107,$A8,Reto1_Datos!$C$18:$C$107,B$5) -> 4207000 | C8: =SUMIFS(Reto1_Datos!$L$18:$L$107,Reto1_Datos!$D$18:$D$107,$A8,Reto1_Datos!$C$18:$C$107,C$5) -> 3407900 | D8: =SUMIFS(Reto1_Datos!$L$18:$L$107,Reto1_Datos!$D$18:$D$107,$A8,Reto1_Datos!$C$18:$C$107,D$5) -> 1110000 | E8: =SUMIFS(Reto1_Datos!$L$18:$L$107,Reto1_Datos!$D$18:$D$107,$A8,Reto1_Datos!$C$18:$C$107,E$5) -> 2479200 | F8: =SUM(B8:E8) -> 11204100
A9: Alajuela | B9: =SUMIFS(Reto1_Datos!$L$18:$L$107,Reto1_Datos!$D$18:$D$107,$A9,Reto1_Datos!$C$18:$C$107,B$5) -> 519800 | C9: =SUMIFS(Reto1_Datos!$L$18:$L$107,Reto1_Datos!$D$18:$D$107,$A9,Reto1_Datos!$C$18:$C$107,C$5) -> 698700 | D9: =SUMIFS(Reto1_Datos!$L$18:$L$107,Reto1_Datos!$D$18:$D$107,$A9,Reto1_Datos!$C$18:$C$107,D$5) -> 686500 | E9: =SUMIFS(Reto1_Datos!$L$18:$L$107,Reto1_Datos!$D$18:$D$107,$A9,Reto1_Datos!$C$18:$C$107,E$5) -> 1669500 | F9: =SUM(B9:E9) -> 3574500
A10: Liberia | B10: =SUMIFS(Reto1_Datos!$L$18:$L$107,Reto1_Datos!$D$18:$D$107,$A10,Reto1_Datos!$C$18:$C$107,B$5) -> 197400 | C10: =SUMIFS(Reto1_Datos!$L$18:$L$107,Reto1_Datos!$D$18:$D$107,$A10,Reto1_Datos!$C$18:$C$107,C$5) -> 654100 | D10: =SUMIFS(Reto1_Datos!$L$18:$L$107,Reto1_Datos!$D$18:$D$107,$A10,Reto1_Datos!$C$18:$C$107,D$5) -> 130400 | E10: =SUMIFS(Reto1_Datos!$L$18:$L$107,Reto1_Datos!$D$18:$D$107,$A10,Reto1_Datos!$C$18:$C$107,E$5) -> 234800 | F10: =SUM(B10:E10) -> 1216700
A13: TABLA 2 — MARGEN BRUTO POR CATEGORÍA (BASE RETO 4)
A14: Categoria | B14: Total Venta | C14: Total Costo | D14: Margen (%)
A15: Construccion | B15: =SUMIF(Reto4_TablaDin!$E$7:$E$96,$A15,Reto4_TablaDin!$J$7:$J$96) -> 3394020 | C15: =SUMIF(Reto4_TablaDin!$E$7:$E$96,$A15,Reto4_TablaDin!$K$7:$K$96) -> 2036239 | D15: =(B15-C15)/B15 -> 0.40005097
A16: Pintura | B16: =SUMIF(Reto4_TablaDin!$E$7:$E$96,$A16,Reto4_TablaDin!$J$7:$J$96) -> 3808403 | C16: =SUMIF(Reto4_TablaDin!$E$7:$E$96,$A16,Reto4_TablaDin!$K$7:$K$96) -> 2284894 | D16: =(B16-C16)/B16 -> 0.40003881
A17: Herramientas | B17: =SUMIF(Reto4_TablaDin!$E$7:$E$96,$A17,Reto4_TablaDin!$J$7:$J$96) -> 11357109 | C17: =SUMIF(Reto4_TablaDin!$E$7:$E$96,$A17,Reto4_TablaDin!$K$7:$K$96) -> 6814019 | D17: =(B17-C17)/B17 -> 0.4000217
A18: Electricos | B18: =SUMIF(Reto4_TablaDin!$E$7:$E$96,$A18,Reto4_TablaDin!$J$7:$J$96) -> 3497247 | C18: =SUMIF(Reto4_TablaDin!$E$7:$E$96,$A18,Reto4_TablaDin!$K$7:$K$96) -> 2098189 | D18: =(B18-C18)/B18 -> 0.40004552
A19: Plomeria | B19: =SUMIF(Reto4_TablaDin!$E$7:$E$96,$A19,Reto4_TablaDin!$J$7:$J$96) -> 1230944 | C19: =SUMIF(Reto4_TablaDin!$E$7:$E$96,$A19,Reto4_TablaDin!$K$7:$K$96) -> 738406 | D19: =(B19-C19)/B19 -> 0.40013031
A22: COMO CALCULAR LA TABLA 1 (ventas por sucursal y trimestre): Use SUMAR.SI.CONJUNTO apuntando a los datos del Reto 1. Necesita dos criterios: que la sucursal coincida con la fila y que el trimestre coincida con la columna. Bloquee con $ los rangos de datos para poder copiar la formula en toda la tabla. COMO CALCULAR LA TABLA 2 (margen por categoria): Para Total Venta y Total Costo, use SUMAR.SI filtrando por categoria. El margen se calcula como (Total Venta - Total Costo) / Total Venta. El resultado expresa que porcentaje de cada colon vendido es ganancia bruta. COMO CREAR LOS GRAFICOS: Seleccione los datos de la tabla correspondiente (incluyendo encabezados). Insertar > Grafico recomendado o elija el tipo directamente. Haga clic derecho sobre el grafico para editar titulo, etiquetas de ejes y formato. Asegurese de que el eje Y del grafico de margen muestre formato de porcentaje.
A24: GRAFICOS REQUERIDOS: (1) Barras agrupadas con Tabla 1: comparar ventas por sucursal entre trimestres. (2) Columnas o linea con Tabla 2: margen % por categoria. Inserte ambos en esta hoja con titulo, etiquetas de ejes y formato profesional.
A26: PREGUNTAS DE ANALISIS GRUPAL
A27: R6-P1 GRUPAL: Cual sucursal tuvo el mayor volumen total de ventas? En que trimestre fue su mejor desempeno? Que elementos del dataset podrian explicar ese resultado?
A28: Heredia tuvo el mayor volumen total de ventas, con 11,204,100 colones acumulados en el ano. Su mejor trimestre fue T1, con 4,207,000 colones. Como en esta version cada sucursal se especializa en una sola categoria de producto, el resultado de Heredia se explica porque concentra las ventas de Herramientas, la categoria de mayor valor unitario del catalogo (hasta 65,000 colones por unidad en el caso del taladro percutor), lo que hace que sus transacciones individuales sean mucho mas grandes que las de las demas sucursales.
A30: R6-P2 GRUPAL: Analizando la evolucion T1 a T4 en la Tabla 1, que tendencia general observa? Hubo crecimiento sostenido, caida o comportamiento irregular? Que deberia anticipar la empresa para el proximo ciclo?
A31: Los totales por trimestre son ₡6.860.150 (T1), ₡6.122.700 (T2), ₡3.481.650 (T3) y ₡6.674.800 (T4). T3 cae un 49,25% respecto de T1 y T4 se recupera. El patrón de este único año es irregular; no prueba estacionalidad ni permite atribuir la caída a vacaciones o clima. Conviene investigar sus causas y simular el efecto de un trimestre débil sobre caja e inventario.
A33: R6-P3 GRUPAL: Segun la Tabla 2, cual categoria tiene el margen mas alto? Que estrategia concreta recomendaria para aprovechar ese margen en terminos de inventario o fuerza de ventas?
A34: En la base del Reto 4, Plomería tiene el margen más alto (40,0130%), apenas 0,0109 puntos porcentuales sobre Herramientas. Herramientas aporta el mayor volumen de ventas, ₡11.357.109. Propondría analizar su reposición según demanda y rotación; no justificaría una decisión comercial en una diferencia de margen tan pequeña.
A36: R6-P4 GRUPAL: Si la empresa tuviera que cerrar la sucursal o descontinuar la categoria de menor desempeno, cual elegiria y por que? Sustente con datos de al menos dos retos diferentes.
A37: Liberia merece una revisión operativa: registra ₡1.216.700 de ventas en la base del Reto 1, un promedio de ₡67.594 por transacción en el Reto 3 y 17 de 18 compras Básico en el Reto 2. Estos indicadores no bastan para recomendar un cierre. Se necesitan costos fijos, utilidad neta, cobertura comercial y demanda potencial antes de decidir.
A39: RECORDATORIO: Las respuestas anteriores son del trio. El analisis escrito INDIVIDUAL tiene sus propias 4 preguntas en la hoja Analisis_Individual y se entrega como documento separado.

Sheet Analisis_Individual
A1: ANALISIS ESCRITO INDIVIDUAL — INSTRUCCIONES Y PREGUNTAS
A2: Esta hoja contiene las instrucciones del DOCUMENTO INDIVIDUAL que entrega CADA estudiante por separado. No va dentro del Excel — es un archivo .docx o .pdf independiente con sus propias respuestas.
A4: CARACTERISTICAS DEL DOCUMENTO INDIVIDUAL
A5: 1. Cada integrante redacta y entrega su propio documento — no se permite copiar entre companeros del mismo trio.
A6: 2. El sistema detecta similitudes automaticamente. Analisis iguales o muy parecidos = penalizacion del 50% en este componente.
A7: 3. Peso en la nota: 35% del total del PE2. Es el componente de mayor peso individual.
A8: 4. Extension: entre 600 y 900 palabras de analisis real (sin contar encabezados, nombre ni listas).
A9: 5. Redaccion: prosa completa en primera persona, sin bullet points. Lenguaje profesional y tecnico.
A11: FORMATO Y ENTREGA
A12: Encabezado obligatorio: | B12: Nombre completo | Carne | Version: XX | Nombre del trio | Curso: BCC 1001 IIC-2026
A13: Nombre del archivo: | B13: PE2_Analisis_VersionXX_Apellido_Nombre.docx (reemplazar XX con su numero de version)
A14: Donde entregarlo: | B14: Campus virtual > Aula BCC 1001 > Actividades > Entrega PE2 - Analisis Individual
A15: Fecha limite: | B15: Martes 18 de agosto, 2026 — 11:59 am
A16: Formato de redaccion: | B16: Texto corrido, primera persona, sin listas de bullet points — respuestas en parrafos completos
A18: LAS 4 PREGUNTAS DEL ANALISIS INDIVIDUAL
A19: Responda las 4 preguntas a continuacion en su documento individual. Sus respuestas deben basarse en los datos concretos de SU VERSION — no en generalidades. Incluya numeros y porcentajes especificos.
A21: AI-P1 — DESEMPENO COMPARATIVO DE SUCURSALES
A22: Analizando los resultados del Reto 3 y el Reto 4 de su version: cual sucursal tuvo el mejor desempeno global considerando tanto el volumen de ventas como el margen de ganancia? Presente los numeros que respaldan su conclusion y explique que factores podrian estar detras de ese resultado.
A23: Borrador / notas personales (no es el entregable):
A26: AI-P2 — TENDENCIA TEMPORAL Y ESTACIONALIDAD
A27: Con base en la Tabla 1 del Reto 6 (ventas por sucursal y trimestre): describa la tendencia general de ventas de T1 a T4 en su version. Identifique si hay alguna sucursal o periodo que rompe el patron general. Que deberia anticipar la empresa para prepararse en el proximo ciclo anual?
A28: Borrador / notas personales (no es el entregable):
A31: AI-P3 — RENTABILIDAD Y DECISION ESTRATEGICA
A32: Usando los datos del margen por categoria (Reto 6, Tabla 2) y la clasificacion del Reto 2: cual es la categoria mas rentable en su version y cual es la de menor margen? Proponga una accion estrategica concreta y cuantificable que la gerencia podria implementar en los proximos 3 meses.
A33: Borrador / notas personales (no es el entregable):
A36: AI-P4 — REFLEXION SOBRE LAS HERRAMIENTAS
... A41: IMPORTANTE: Use este espacio solo como borrador. El entregable real es un documento .docx o .pdf con prosa continua, encabezado correcto y redaccion profesional en primera persona.

Sheet Tips_Defensa
A1: GUIA DE PREPARACION PARA LA DEFENSA ORAL
A2: La defensa es INDIVIDUAL. El evaluador le hara 2 preguntas sobre su propio trabajo. Duracion: aprox. 5 minutos por persona. Sin computadora, celular ni notas. Esta guia tiene ejemplos reales del tipo de preguntas y como responderlas bien.
A4: BLOQUE 1 — FORMULAS Y FUNCIONES: EJEMPLOS DE PREGUNTAS Y COMO RESPONDERLAS
A5: Ejemplo de pregunta: 'Explique que hace ESPACIOS() y por que fue necesaria en el Reto 1.'
A6: Respuesta solida: 'ESPACIOS elimina los espacios en blanco al inicio y al final de una cadena de texto. En el Reto 1 la usamos porque algunos codigos de producto tenian un espacio extra que impedia que BUSCARV los encontrara en el catalogo — devolviendo error #N/A. Al limpiarlos con ESPACIOS primero, el BUSCARV funciona correctamente.'
A8: Ejemplo de pregunta: 'Cuales son los 4 argumentos del BUSCARV y que hace cada uno?'
A9: Respuesta solida: 'El primer argumento es el valor que busca — en nuestro caso el codigo limpio. El segundo es el rango de la tabla donde busca, que es el catalogo de productos. El tercero es el numero de columna del catalogo que quiero obtener: 2 para el nombre, 4 para el precio. El cuarto es 0, que significa coincidencia exacta y es el que usamos siempre cuando los datos son texto o codigos.'
A11: Ejemplo de pregunta: 'Por que en el SI anidado del Reto 2 empezo por 500,000 y no por 200,000?'
A12: Respuesta solida: 'Porque Excel evalua las condiciones en orden. Si hubiera puesto primero el umbral de 200,000, cualquier venta de 500,000 o mas tambien cumpliria esa condicion y quedaria clasificada como Regular antes de llegar a evaluarse como Premium. Al empezar por el umbral mas alto, garantizamos que solo caigan en Premium las que realmente superan los 500,000.'
A14: Ejemplo de pregunta: 'En PAGO, por que el monto del prestamo va con signo negativo?'
A15: En PAGO, el valor actual y las cuotas tienen signos opuestos por la convención de flujos. Si registramos el préstamo recibido como positivo, las cuotas son negativas. Aquí se usa -monto para presentar la cuota como un importe positivo de pago.
A18: BLOQUE 2 — INTERPRETACION DE RESULTADOS: EJEMPLOS CON NUMEROS HIPOTETICOS
... A55: La defensa no es un examen de memoria — es una conversacion sobre su propio trabajo. Si hizo los retos con honestidad y los entendio, tiene todo lo que necesita para aprobarla.
